<?xml version="1.0" ?>
<!-- =================================================================================== -->
<!-- |    This document was autogenerated by xacro from robot_core.xacro               | -->
<!-- |    EDITING THIS FILE BY HAND IS NOT RECOMMENDED                                 | -->
<!-- =================================================================================== -->
<robot name="magnecko">
  <!-- Specify some standard inertial calculations https://en.wikipedia.org/wiki/List_of_moments_of_inertia -->
  <!-- These make use of xacro's mathematical functionality -->
  <!-- BASE LINK -->
  <!-- <link name="world">
    </link> -->
  <!-- <link name="world">
    </link> -->
  <!-- CHASSIS LINK -->
  <!-- <joint name="chassis_joint" type="fixed">
        <parent link="world"/>
        <child link="chassis"/>
        <origin xyz="0 0 0"/>
    </joint> -->
  <link name="chassis">
    <visual>
      <origin xyz="0 0 0"/>
      <geometry>
        <box size="0.2 0.2 0.1"/>
      </geometry>
      <material name="white"/>
    </visual>
    <collision>
      <origin xyz="0 0 0"/>
      <geometry>
        <box size="0.14 0.14 0.1"/>
      </geometry>
      <surface>
        <contact>
          <ode>
            <kp>1e15</kp>
            <kd>1e13</kd>
          </ode>
        </contact>
      </surface>
    </collision>
    <inertial>
      <origin rpy="0 0 0" xyz="0 0 0"/>
      <mass value="0.7"/>
      <inertia ixx="0.002916666666666667" ixy="0.0" ixz="0.0" iyy="0.002916666666666667" iyz="0.0" izz="0.004666666666666667"/>
    </inertial>
  </link>
  <!-- First Arm -->
  <joint name="first_arm_yaw" type="revolute">
    <parent link="chassis"/>
    <child link="first_arm_link"/>
    <origin rpy="0 0 0.7853981633974483" xyz="0.1 0.1 0"/>
    <axis xyz="0 0 1"/>
    <dynamics damping="0.8" friction="0.0"/>
    <limit effort="200.0" lower="-3.1" upper="3.1" velocity="1.0"/>
  </joint>
  <link name="first_arm_link">
    <visual>
      <origin rpy="0 0 0" xyz="0.0 0.0 0.0"/>
      <geometry>
        <sphere radius="0.025"/>
      </geometry>
      <material name="blue"/>
    </visual>
    <collision>
      <origin rpy="0 0 0" xyz="0.0 0.0 0.0"/>
      <geometry>
        <sphere radius="0.025"/>
      </geometry>
    </collision>
    <inertial>
      <origin rpy="0 0 0" xyz="0.0 0.0 0.0"/>
      <mass value="0.5"/>
      <inertia ixx="0.00012500000000000003" ixy="0.0" ixz="0.0" iyy="0.00012500000000000003" iyz="0.0" izz="0.00012500000000000003"/>
    </inertial>
  </link>
  <joint name="first_arm_pitch" type="revolute">
    <parent link="first_arm_link"/>
    <child link="first_arm"/>
    <origin rpy="0 0 0" xyz="0.0 0.0 0.0"/>
    <axis xyz="0 1 0"/>
    <dynamics damping="0.8" friction="0.0"/>
    <limit effort="200.0" lower="-3.1" upper="3.1" velocity="1.0"/>
  </joint>
  <link name="first_arm">
    <visual>
      <origin rpy="-1.5707963267948966 0 1.5707963267948966" xyz="0.1 0 0"/>
      <geometry>
        <cylinder length="0.2" radius="0.02"/>
      </geometry>
      <material name="blue"/>
    </visual>
    <collision>
      <origin rpy="-1.5707963267948966 0 1.5707963267948966" xyz="0.1 0 0"/>
      <geometry>
        <cylinder length="0.14500000000000002" radius="0.02"/>
      </geometry>
    </collision>
    <inertial>
      <origin rpy="-1.5707963267948966 0 1.5707963267948966" xyz="0.1 0 0"/>
      <mass value="0.4"/>
      <inertia ixx="0.0013733333333333336" ixy="0.0" ixz="0.0" iyy="0.0013733333333333336" iyz="0.0" izz="8e-05"/>
    </inertial>
  </link>
  <joint name="first_knee_joint" type="revolute">
    <parent link="first_arm"/>
    <child link="first_knee"/>
    <origin rpy="0 0 0" xyz="0.2 0.0 0.0"/>
    <axis xyz="0 1 0"/>
    <dynamics damping="0.8" friction="0.0"/>
    <limit effort="200.0" lower="-3.1" upper="3.1" velocity="1.0"/>
  </joint>
  <link name="first_knee">
    <visual>
      <origin rpy="-1.5707963267948966 0 1.5707963267948966" xyz="0.045 0 0"/>
      <geometry>
        <cylinder length="0.09" radius="0.02"/>
      </geometry>
      <material name="green"/>
    </visual>
    <collision>
      <origin rpy="-1.5707963267948966 0 1.5707963267948966" xyz="0.045 0 0"/>
      <geometry>
        <cylinder length="0.09" radius="0.02"/>
      </geometry>
      <material name="green"/>
    </collision>
    <inertial>
      <origin rpy="-1.5707963267948966 0 1.5707963267948966" xyz="0.045 0 0"/>
      <mass value="0.4"/>
      <inertia ixx="0.00030999999999999995" ixy="0.0" ixz="0.0" iyy="0.00030999999999999995" iyz="0.0" izz="8e-05"/>
    </inertial>
  </link>
  <joint name="first_ankle_yaw_joint" type="revolute">
    <parent link="first_knee"/>
    <child link="first_ankle_yaw"/>
    <origin rpy="0 0 0" xyz="0.09 0.0 0.0"/>
    <axis xyz="1 0 0"/>
    <dynamics damping="0.8" friction="0.0"/>
    <limit effort="200.0" lower="-3.1" upper="3.1" velocity="1.0"/>
  </joint>
  <link name="first_ankle_yaw">
    <visual>
      <origin rpy="-1.5707963267948966 0 1.5707963267948966" xyz="0.025 0 0"/>
      <geometry>
        <cylinder length="0.05" radius="0.02"/>
      </geometry>
      <material name="green"/>
    </visual>
    <collision>
      <origin rpy="-1.5707963267948966 0 1.5707963267948966" xyz="0.025 0 0"/>
      <geometry>
        <cylinder length="0.05" radius="0.02"/>
      </geometry>
      <material name="green"/>
    </collision>
    <inertial>
      <origin rpy="-1.5707963267948966 0 1.5707963267948966" xyz="0.025 0 0"/>
      <mass value="0.2"/>
      <inertia ixx="6.166666666666667e-05" ixy="0.0" ixz="0.0" iyy="6.166666666666667e-05" iyz="0.0" izz="4e-05"/>
    </inertial>
  </link>
  <joint name="first_ankle_roll_joint" type="revolute">
    <parent link="first_ankle_yaw"/>
    <child link="first_ankle_roll"/>
    <origin rpy="0 0 0" xyz="0.065 0 0"/>
    <axis xyz="0 0 1"/>
    <dynamics damping="0.8" friction="0.0"/>
    <limit effort="200.0" lower="-3.1" upper="3.1" velocity="1.0"/>
  </joint>
  <link name="first_ankle_roll">
    <visual>
      <origin rpy="0 0 0" xyz="0.0 0.0 0.0"/>
      <geometry>
        <sphere radius="0.015"/>
      </geometry>
      <material name="blue"/>
    </visual>
    <collision>
      <origin rpy="0 0 0" xyz="0.0 0.0 0.0"/>
      <geometry>
        <sphere radius="0.0135"/>
      </geometry>
    </collision>
    <inertial>
      <origin rpy="0 0 0" xyz="0.0 0.0 0.0"/>
      <mass value="0.2"/>
      <inertia ixx="1.8000000000000004e-05" ixy="0.0" ixz="0.0" iyy="1.8000000000000004e-05" iyz="0.0" izz="1.8000000000000004e-05"/>
    </inertial>
  </link>
  <joint name="first_ankle_pitch_joint" type="revolute">
    <parent link="first_ankle_roll"/>
    <child link="first_foot"/>
    <origin rpy="0 0 0" xyz="0 0 0"/>
    <axis xyz="0 1 0"/>
    <dynamics damping="0.8" friction="0.0"/>
    <limit effort="200.0" lower="-3.1" upper="3.1" velocity="1.0"/>
  </joint>
  <link name="first_foot">
    <visual>
      <origin rpy="0 0 0" xyz="0.03 0.0 0.0"/>
      <geometry>
        <box size="0.03 0.07 0.07"/>
      </geometry>
      <material name="blue"/>
    </visual>
    <collision>
      <origin rpy="0 0 0" xyz="0.03 0.0 0.0"/>
      <geometry>
        <box size="0.03 0.07 0.07"/>
      </geometry>
    </collision>
    <inertial>
      <origin rpy="0 0 0" xyz="0.03 0.0 0.0"/>
      <mass value="1.0"/>
      <inertia ixx="0.0008166666666666667" ixy="0.0" ixz="0.0" iyy="0.00048333333333333334" iyz="0.0" izz="0.00048333333333333334"/>
    </inertial>
  </link>
  <!-- Second Arm -->
  <joint name="second_arm_yaw" type="revolute">
    <parent link="chassis"/>
    <child link="second_arm_link"/>
    <origin rpy="0 0 -0.7853981633974483" xyz="0.1 -0.1 0"/>
    <axis xyz="0 0 1"/>
    <dynamics damping="0.8" friction="0.0"/>
    <limit effort="200.0" lower="-3.1" upper="3.1" velocity="1.0"/>
  </joint>
  <link name="second_arm_link">
    <visual>
      <origin rpy="0 0 0" xyz="0.0 0.0 0.0"/>
      <geometry>
        <sphere radius="0.025"/>
      </geometry>
      <material name="blue"/>
    </visual>
    <collision>
      <origin rpy="0 0 0" xyz="0.0 0.0 0.0"/>
      <geometry>
        <sphere radius="0.025"/>
      </geometry>
    </collision>
    <inertial>
      <origin rpy="0 0 0" xyz="0.0 0.0 0.0"/>
      <mass value="0.5"/>
      <inertia ixx="0.00012500000000000003" ixy="0.0" ixz="0.0" iyy="0.00012500000000000003" iyz="0.0" izz="0.00012500000000000003"/>
    </inertial>
  </link>
  <joint name="second_arm_pitch" type="revolute">
    <parent link="second_arm_link"/>
    <child link="second_arm"/>
    <origin rpy="0 0 0" xyz="0.0 0.0 0.0"/>
    <axis xyz="0 1 0"/>
    <dynamics damping="0.8" friction="0.0"/>
    <limit effort="200.0" lower="-3.1" upper="3.1" velocity="1.0"/>
  </joint>
  <link name="second_arm">
    <visual>
      <origin rpy="-1.5707963267948966 0 1.5707963267948966" xyz="0.1 0 0"/>
      <geometry>
        <cylinder length="0.2" radius="0.02"/>
      </geometry>
      <material name="blue"/>
    </visual>
    <collision>
      <origin rpy="-1.5707963267948966 0 1.5707963267948966" xyz="0.1 0 0"/>
      <geometry>
        <cylinder length="0.14500000000000002" radius="0.02"/>
      </geometry>
    </collision>
    <inertial>
      <origin rpy="-1.5707963267948966 0 1.5707963267948966" xyz="0.1 0 0"/>
      <mass value="0.4"/>
      <inertia ixx="0.0013733333333333336" ixy="0.0" ixz="0.0" iyy="0.0013733333333333336" iyz="0.0" izz="8e-05"/>
    </inertial>
  </link>
  <joint name="second_knee_joint" type="revolute">
    <parent link="second_arm"/>
    <child link="second_knee"/>
    <origin rpy="0 0 0" xyz="0.2 0.0 0.0"/>
    <axis xyz="0 1 0"/>
    <dynamics damping="0.8" friction="0.0"/>
    <limit effort="200.0" lower="-3.1" upper="3.1" velocity="1.0"/>
  </joint>
  <link name="second_knee">
    <visual>
      <origin rpy="-1.5707963267948966 0 1.5707963267948966" xyz="0.045 0 0"/>
      <geometry>
        <cylinder length="0.09" radius="0.02"/>
      </geometry>
      <material name="green"/>
    </visual>
    <collision>
      <origin rpy="-1.5707963267948966 0 1.5707963267948966" xyz="0.045 0 0"/>
      <geometry>
        <cylinder length="0.09" radius="0.02"/>
      </geometry>
      <material name="green"/>
    </collision>
    <inertial>
      <origin rpy="-1.5707963267948966 0 1.5707963267948966" xyz="0.045 0 0"/>
      <mass value="0.4"/>
      <inertia ixx="0.00030999999999999995" ixy="0.0" ixz="0.0" iyy="0.00030999999999999995" iyz="0.0" izz="8e-05"/>
    </inertial>
  </link>
  <joint name="second_ankle_yaw_joint" type="revolute">
    <parent link="second_knee"/>
    <child link="second_ankle_yaw"/>
    <origin rpy="0 0 0" xyz="0.09 0.0 0.0"/>
    <axis xyz="1 0 0"/>
    <dynamics damping="0.8" friction="0.0"/>
    <limit effort="200.0" lower="-3.1" upper="3.1" velocity="1.0"/>
  </joint>
  <link name="second_ankle_yaw">
    <visual>
      <origin rpy="-1.5707963267948966 0 1.5707963267948966" xyz="0.025 0 0"/>
      <geometry>
        <cylinder length="0.05" radius="0.02"/>
      </geometry>
      <material name="green"/>
    </visual>
    <collision>
      <origin rpy="-1.5707963267948966 0 1.5707963267948966" xyz="0.025 0 0"/>
      <geometry>
        <cylinder length="0.05" radius="0.02"/>
      </geometry>
      <material name="green"/>
    </collision>
    <inertial>
      <origin rpy="-1.5707963267948966 0 1.5707963267948966" xyz="0.025 0 0"/>
      <mass value="0.2"/>
      <inertia ixx="6.166666666666667e-05" ixy="0.0" ixz="0.0" iyy="6.166666666666667e-05" iyz="0.0" izz="4e-05"/>
    </inertial>
  </link>
  <joint name="second_ankle_roll_joint" type="revolute">
    <parent link="second_ankle_yaw"/>
    <child link="second_ankle_roll"/>
    <origin rpy="0 0 0" xyz="0.065 0 0"/>
    <axis xyz="0 0 1"/>
    <dynamics damping="0.8" friction="0.0"/>
    <limit effort="200.0" lower="-3.1" upper="3.1" velocity="1.0"/>
  </joint>
  <link name="second_ankle_roll">
    <visual>
      <origin rpy="0 0 0" xyz="0.0 0.0 0.0"/>
      <geometry>
        <sphere radius="0.015"/>
      </geometry>
      <material name="blue"/>
    </visual>
    <collision>
      <origin rpy="0 0 0" xyz="0.0 0.0 0.0"/>
      <geometry>
        <sphere radius="0.0135"/>
      </geometry>
    </collision>
    <inertial>
      <origin rpy="0 0 0" xyz="0.0 0.0 0.0"/>
      <mass value="0.2"/>
      <inertia ixx="1.8000000000000004e-05" ixy="0.0" ixz="0.0" iyy="1.8000000000000004e-05" iyz="0.0" izz="1.8000000000000004e-05"/>
    </inertial>
  </link>
  <joint name="second_ankle_pitch_joint" type="revolute">
    <parent link="second_ankle_roll"/>
    <child link="second_foot"/>
    <origin rpy="0 0 0" xyz="0 0 0"/>
    <axis xyz="0 1 0"/>
    <dynamics damping="0.8" friction="0.0"/>
    <limit effort="200.0" lower="-3.1" upper="3.1" velocity="1.0"/>
  </joint>
  <link name="second_foot">
    <visual>
      <origin rpy="0 0 0" xyz="0.03 0.0 0.0"/>
      <geometry>
        <box size="0.03 0.07 0.07"/>
      </geometry>
      <material name="blue"/>
    </visual>
    <collision>
      <origin rpy="0 0 0" xyz="0.03 0.0 0.0"/>
      <geometry>
        <box size="0.03 0.07 0.07"/>
      </geometry>
    </collision>
    <inertial>
      <origin rpy="0 0 0" xyz="0.03 0.0 0.0"/>
      <mass value="1.0"/>
      <inertia ixx="0.0008166666666666667" ixy="0.0" ixz="0.0" iyy="0.00048333333333333334" iyz="0.0" izz="0.00048333333333333334"/>
    </inertial>
  </link>
  <!-- third Arm -->
  <joint name="third_arm_yaw" type="revolute">
    <parent link="chassis"/>
    <child link="third_arm_link"/>
    <origin rpy="0 0 -2.356194490192345" xyz="-0.1 -0.1 0"/>
    <axis xyz="0 0 1"/>
    <dynamics damping="0.8" friction="0.0"/>
    <limit effort="200.0" lower="-3.1" upper="3.1" velocity="1.0"/>
  </joint>
  <link name="third_arm_link">
    <visual>
      <origin rpy="0 0 0" xyz="0.0 0.0 0.0"/>
      <geometry>
        <sphere radius="0.025"/>
      </geometry>
      <material name="blue"/>
    </visual>
    <collision>
      <origin rpy="0 0 0" xyz="0.0 0.0 0.0"/>
      <geometry>
        <sphere radius="0.025"/>
      </geometry>
    </collision>
    <inertial>
      <origin rpy="0 0 0" xyz="0.0 0.0 0.0"/>
      <mass value="0.5"/>
      <inertia ixx="0.00012500000000000003" ixy="0.0" ixz="0.0" iyy="0.00012500000000000003" iyz="0.0" izz="0.00012500000000000003"/>
    </inertial>
  </link>
  <joint name="third_arm_pitch" type="revolute">
    <parent link="third_arm_link"/>
    <child link="third_arm"/>
    <origin rpy="0 0 0" xyz="0.0 0.0 0.0"/>
    <axis xyz="0 1 0"/>
    <dynamics damping="0.8" friction="0.0"/>
    <limit effort="200.0" lower="-3.1" upper="3.1" velocity="1.0"/>
  </joint>
  <link name="third_arm">
    <visual>
      <origin rpy="-1.5707963267948966 0 1.5707963267948966" xyz="0.1 0 0"/>
      <geometry>
        <cylinder length="0.2" radius="0.02"/>
      </geometry>
      <material name="blue"/>
    </visual>
    <collision>
      <origin rpy="-1.5707963267948966 0 1.5707963267948966" xyz="0.1 0 0"/>
      <geometry>
        <cylinder length="0.14500000000000002" radius="0.02"/>
      </geometry>
    </collision>
    <inertial>
      <origin rpy="-1.5707963267948966 0 1.5707963267948966" xyz="0.1 0 0"/>
      <mass value="0.4"/>
      <inertia ixx="0.0013733333333333336" ixy="0.0" ixz="0.0" iyy="0.0013733333333333336" iyz="0.0" izz="8e-05"/>
    </inertial>
  </link>
  <joint name="third_knee_joint" type="revolute">
    <parent link="third_arm"/>
    <child link="third_knee"/>
    <origin rpy="0 0 0" xyz="0.2 0.0 0.0"/>
    <axis xyz="0 1 0"/>
    <dynamics damping="0.8" friction="0.0"/>
    <limit effort="200.0" lower="-3.1" upper="3.1" velocity="1.0"/>
  </joint>
  <link name="third_knee">
    <visual>
      <origin rpy="-1.5707963267948966 0 1.5707963267948966" xyz="0.045 0 0"/>
      <geometry>
        <cylinder length="0.09" radius="0.02"/>
      </geometry>
      <material name="green"/>
    </visual>
    <collision>
      <origin rpy="-1.5707963267948966 0 1.5707963267948966" xyz="0.045 0 0"/>
      <geometry>
        <cylinder length="0.09" radius="0.02"/>
      </geometry>
      <material name="green"/>
    </collision>
    <inertial>
      <origin rpy="-1.5707963267948966 0 1.5707963267948966" xyz="0.045 0 0"/>
      <mass value="0.4"/>
      <inertia ixx="0.00030999999999999995" ixy="0.0" ixz="0.0" iyy="0.00030999999999999995" iyz="0.0" izz="8e-05"/>
    </inertial>
  </link>
  <joint name="third_ankle_yaw_joint" type="revolute">
    <parent link="third_knee"/>
    <child link="third_ankle_yaw"/>
    <origin rpy="0 0 0" xyz="0.09 0.0 0.0"/>
    <axis xyz="1 0 0"/>
    <dynamics damping="0.8" friction="0.0"/>
    <limit effort="200.0" lower="-3.1" upper="3.1" velocity="1.0"/>
  </joint>
  <link name="third_ankle_yaw">
    <visual>
      <origin rpy="-1.5707963267948966 0 1.5707963267948966" xyz="0.025 0 0"/>
      <geometry>
        <cylinder length="0.05" radius="0.02"/>
      </geometry>
      <material name="green"/>
    </visual>
    <collision>
      <origin rpy="-1.5707963267948966 0 1.5707963267948966" xyz="0.025 0 0"/>
      <geometry>
        <cylinder length="0.05" radius="0.02"/>
      </geometry>
      <material name="green"/>
    </collision>
    <inertial>
      <origin rpy="-1.5707963267948966 0 1.5707963267948966" xyz="0.025 0 0"/>
      <mass value="0.2"/>
      <inertia ixx="6.166666666666667e-05" ixy="0.0" ixz="0.0" iyy="6.166666666666667e-05" iyz="0.0" izz="4e-05"/>
    </inertial>
  </link>
  <joint name="third_ankle_roll_joint" type="revolute">
    <parent link="third_ankle_yaw"/>
    <child link="third_ankle_roll"/>
    <origin rpy="0 0 0" xyz="0.065 0 0"/>
    <axis xyz="0 0 1"/>
    <dynamics damping="0.8" friction="0.0"/>
    <limit effort="200.0" lower="-3.1" upper="3.1" velocity="1.0"/>
  </joint>
  <link name="third_ankle_roll">
    <visual>
      <origin rpy="0 0 0" xyz="0.0 0.0 0.0"/>
      <geometry>
        <sphere radius="0.015"/>
      </geometry>
      <material name="blue"/>
    </visual>
    <collision>
      <origin rpy="0 0 0" xyz="0.0 0.0 0.0"/>
      <geometry>
        <sphere radius="0.0135"/>
      </geometry>
    </collision>
    <inertial>
      <origin rpy="0 0 0" xyz="0.0 0.0 0.0"/>
      <mass value="0.2"/>
      <inertia ixx="1.8000000000000004e-05" ixy="0.0" ixz="0.0" iyy="1.8000000000000004e-05" iyz="0.0" izz="1.8000000000000004e-05"/>
    </inertial>
  </link>
  <joint name="third_ankle_pitch_joint" type="revolute">
    <parent link="third_ankle_roll"/>
    <child link="third_foot"/>
    <origin rpy="0 0 0" xyz="0 0 0"/>
    <axis xyz="0 1 0"/>
    <dynamics damping="0.8" friction="0.0"/>
    <limit effort="200.0" lower="-3.1" upper="3.1" velocity="1.0"/>
  </joint>
  <link name="third_foot">
    <visual>
      <origin rpy="0 0 0" xyz="0.03 0.0 0.0"/>
      <geometry>
        <box size="0.03 0.07 0.07"/>
      </geometry>
      <material name="blue"/>
    </visual>
    <collision>
      <origin rpy="0 0 0" xyz="0.03 0.0 0.0"/>
      <geometry>
        <box size="0.03 0.07 0.07"/>
      </geometry>
    </collision>
    <inertial>
      <origin rpy="0 0 0" xyz="0.03 0.0 0.0"/>
      <mass value="1.0"/>
      <inertia ixx="0.0008166666666666667" ixy="0.0" ixz="0.0" iyy="0.00048333333333333334" iyz="0.0" izz="0.00048333333333333334"/>
    </inertial>
  </link>
  <!-- fourth Arm -->
  <joint name="fourth_arm_yaw" type="revolute">
    <parent link="chassis"/>
    <child link="fourth_arm_link"/>
    <origin rpy="0 0 2.356194490192345" xyz="-0.1 0.1 0"/>
    <axis xyz="0 0 1"/>
    <dynamics damping="0.8" friction="0.0"/>
    <limit effort="200.0" lower="-3.1" upper="3.1" velocity="1.0"/>
  </joint>
  <link name="fourth_arm_link">
    <visual>
      <origin rpy="0 0 0" xyz="0.0 0.0 0.0"/>
      <geometry>
        <sphere radius="0.025"/>
      </geometry>
      <material name="blue"/>
    </visual>
    <collision>
      <origin rpy="0 0 0" xyz="0.0 0.0 0.0"/>
      <geometry>
        <sphere radius="0.025"/>
      </geometry>
    </collision>
    <inertial>
      <origin rpy="0 0 0" xyz="0.0 0.0 0.0"/>
      <mass value="0.5"/>
      <inertia ixx="0.00012500000000000003" ixy="0.0" ixz="0.0" iyy="0.00012500000000000003" iyz="0.0" izz="0.00012500000000000003"/>
    </inertial>
  </link>
  <joint name="fourth_arm_pitch" type="revolute">
    <parent link="fourth_arm_link"/>
    <child link="fourth_arm"/>
    <origin rpy="0 0 0" xyz="0.0 0.0 0.0"/>
    <axis xyz="0 1 0"/>
    <dynamics damping="0.8" friction="0.0"/>
    <limit effort="200.0" lower="-3.1" upper="3.1" velocity="1.0"/>
  </joint>
  <link name="fourth_arm">
    <visual>
      <origin rpy="-1.5707963267948966 0 1.5707963267948966" xyz="0.1 0 0"/>
      <geometry>
        <cylinder length="0.2" radius="0.02"/>
      </geometry>
      <material name="blue"/>
    </visual>
    <collision>
      <origin rpy="-1.5707963267948966 0 1.5707963267948966" xyz="0.1 0 0"/>
      <geometry>
        <cylinder length="0.14500000000000002" radius="0.02"/>
      </geometry>
    </collision>
    <inertial>
      <origin rpy="-1.5707963267948966 0 1.5707963267948966" xyz="0.1 0 0"/>
      <mass value="0.4"/>
      <inertia ixx="0.0013733333333333336" ixy="0.0" ixz="0.0" iyy="0.0013733333333333336" iyz="0.0" izz="8e-05"/>
    </inertial>
  </link>
  <joint name="fourth_knee_joint" type="revolute">
    <parent link="fourth_arm"/>
    <child link="fourth_knee"/>
    <origin rpy="0 0 0" xyz="0.2 0.0 0.0"/>
    <axis xyz="0 1 0"/>
    <dynamics damping="0.8" friction="0.0"/>
    <limit effort="200.0" lower="-3.1" upper="3.1" velocity="1.0"/>
  </joint>
  <link name="fourth_knee">
    <visual>
      <origin rpy="-1.5707963267948966 0 1.5707963267948966" xyz="0.045 0 0"/>
      <geometry>
        <cylinder length="0.09" radius="0.02"/>
      </geometry>
      <material name="green"/>
    </visual>
    <collision>
      <origin rpy="-1.5707963267948966 0 1.5707963267948966" xyz="0.045 0 0"/>
      <geometry>
        <cylinder length="0.09" radius="0.02"/>
      </geometry>
      <material name="green"/>
    </collision>
    <inertial>
      <origin rpy="-1.5707963267948966 0 1.5707963267948966" xyz="0.045 0 0"/>
      <mass value="0.4"/>
      <inertia ixx="0.00030999999999999995" ixy="0.0" ixz="0.0" iyy="0.00030999999999999995" iyz="0.0" izz="8e-05"/>
    </inertial>
  </link>
  <joint name="fourth_ankle_yaw_joint" type="revolute">
    <parent link="fourth_knee"/>
    <child link="fourth_ankle_yaw"/>
    <origin rpy="0 0 0" xyz="0.09 0.0 0.0"/>
    <axis xyz="1 0 0"/>
    <dynamics damping="0.8" friction="0.0"/>
    <limit effort="200.0" lower="-3.1" upper="3.1" velocity="1.0"/>
  </joint>
  <link name="fourth_ankle_yaw">
    <visual>
      <origin rpy="-1.5707963267948966 0 1.5707963267948966" xyz="0.025 0 0"/>
      <geometry>
        <cylinder length="0.05" radius="0.02"/>
      </geometry>
      <material name="green"/>
    </visual>
    <collision>
      <origin rpy="-1.5707963267948966 0 1.5707963267948966" xyz="0.025 0 0"/>
      <geometry>
        <cylinder length="0.05" radius="0.02"/>
      </geometry>
      <material name="green"/>
    </collision>
    <inertial>
      <origin rpy="-1.5707963267948966 0 1.5707963267948966" xyz="0.025 0 0"/>
      <mass value="0.2"/>
      <inertia ixx="6.166666666666667e-05" ixy="0.0" ixz="0.0" iyy="6.166666666666667e-05" iyz="0.0" izz="4e-05"/>
    </inertial>
  </link>
  <joint name="fourth_ankle_roll_joint" type="revolute">
    <parent link="fourth_ankle_yaw"/>
    <child link="fourth_ankle_roll"/>
    <origin rpy="0 0 0" xyz="0.065 0 0"/>
    <axis xyz="0 0 1"/>
    <dynamics damping="0.8" friction="0.0"/>
    <limit effort="200.0" lower="-3.1" upper="3.1" velocity="1.0"/>
  </joint>
  <link name="fourth_ankle_roll">
    <visual>
      <origin rpy="0 0 0" xyz="0.0 0.0 0.0"/>
      <geometry>
        <sphere radius="0.015"/>
      </geometry>
      <material name="blue"/>
    </visual>
    <collision>
      <origin rpy="0 0 0" xyz="0.0 0.0 0.0"/>
      <geometry>
        <sphere radius="0.0135"/>
      </geometry>
    </collision>
    <inertial>
      <origin rpy="0 0 0" xyz="0.0 0.0 0.0"/>
      <mass value="0.2"/>
      <inertia ixx="1.8000000000000004e-05" ixy="0.0" ixz="0.0" iyy="1.8000000000000004e-05" iyz="0.0" izz="1.8000000000000004e-05"/>
    </inertial>
  </link>
  <joint name="fourth_ankle_pitch_joint" type="revolute">
    <parent link="fourth_ankle_roll"/>
    <child link="fourth_foot"/>
    <origin rpy="0 0 0" xyz="0 0 0"/>
    <axis xyz="0 1 0"/>
    <dynamics damping="0.8" friction="0.0"/>
    <limit effort="200.0" lower="-3.1" upper="3.1" velocity="1.0"/>
  </joint>
  <link name="fourth_foot">
    <visual>
      <origin rpy="0 0 0" xyz="0.03 0.0 0.0"/>
      <geometry>
        <box size="0.03 0.07 0.07"/>
      </geometry>
      <material name="blue"/>
    </visual>
    <collision>
      <origin rpy="0 0 0" xyz="0.03 0.0 0.0"/>
      <geometry>
        <box size="0.03 0.07 0.07"/>
      </geometry>
    </collision>
    <inertial>
      <origin rpy="0 0 0" xyz="0.03 0.0 0.0"/>
      <mass value="1.0"/>
      <inertia ixx="0.0008166666666666667" ixy="0.0" ixz="0.0" iyy="0.00048333333333333334" iyz="0.0" izz="0.00048333333333333334"/>
    </inertial>
  </link>
</robot>